<?xml version="1.0"?>
<!-- created with Phobos 0.7 -->
  <robot name="blackbird">

  <!-- defube some colors -->
  
      <material
        name="ceramic">
        <color
          rgba="0.79216 0.81961 0.93333 1" />
      </material>

      <material
        name="teal">
        <color
          rgba="0.184313 0.92157 0.92157 1" />
      </material>

    <link name="world"/>

    <link name="l_ab_ad">
      <inertial>
        <origin xyz="8e-05 0.02446 -0.00146" rpy="0 0 0"/>
        <mass value="1.2"/>
        <inertia ixx="0.00196" ixy="0" ixz="0" iyy="0.00133" iyz="-2e-05" izz="0.0023"/>
      </inertial>
      <visual name="mesh.002">
        <origin xyz="8e-05 0.02446 -0.00146" rpy="0 0 0"/>
        <geometry>
          <mesh filename="package://ETH_biped/meshes/blackbird/Assembly_Mockup_v27_003.stl" scale="1.0 1.0 1.0"/>
        </geometry>
        <material name="Material"/>
      </visual>
      <collision name="mesh.002">
        <origin xyz="0 0.00015 -0.00044" rpy="0 0 0"/>
        <geometry>
          <cylinder radius="0.055" length="0.0759"/>
        </geometry>
      </collision>
    </link>

    <link name="l_foot">
      <inertial>
        <origin xyz="0 0.00325 -0.02828" rpy="0 0 0"/>
        <mass value="0.5"/>
        <inertia ixx="0.00163" ixy="0" ixz="0" iyy="0.001" iyz="-5e-05" izz="0.00151"/>
      </inertial>
      <visual name="Cylinder">
        <origin xyz="0 -0.07 -0.05247" rpy="1.5708 0 0"/>
        <geometry>
          <cylinder radius="0.01" length="0.04"/>
        </geometry>
        <material name="ceramic"/>
      </visual>
      <visual name="Cylinder.001">
        <origin xyz="0 0.07 -0.05247" rpy="1.5708 0 0"/>
        <geometry>
          <cylinder radius="0.01" length="0.04"/>
        </geometry>
        <material name="Material"/>
      </visual>
      <visual name="Sphere">
        <origin xyz="0 -0.09 -0.05247" rpy="1.5708 0 0"/>
        <geometry>
          <sphere radius="0.01"/>
        </geometry>
        <material name="Material"/>
      </visual>
      <visual name="Sphere.001">
        <origin xyz="0 -0.05 -0.05247" rpy="1.5708 0 0"/>
        <geometry>
          <sphere radius="0.01"/>
        </geometry>
        <material name="Material"/>
      </visual>
      <visual name="Sphere.002">
        <origin xyz="0 0.09 -0.05247" rpy="1.5708 0 0"/>
        <geometry>
          <sphere radius="0.01"/>
        </geometry>
        <material name="Material"/>
      </visual>
      <visual name="Sphere.003">
        <origin xyz="0 0.05 -0.05247" rpy="1.5708 0 0"/>
        <geometry>
          <sphere radius="0.01"/>
        </geometry>
        <material name="Material"/>
      </visual>
      <visual name="mesh.009">
        <origin xyz="0 0.00325 -0.02828" rpy="0 0 0"/>
        <geometry>
          <mesh filename="package://ETH_biped/meshes/blackbird/Assembly_Mockup_v27_012.stl" scale="1.0 1.0 1.0"/>
        </geometry>
        <material name="Material"/>
      </visual>
      <collision name="Sphere">
        <origin xyz="0 -0.09 -0.04" rpy="1.5708 0 0"/>
        <geometry>
          <sphere radius="0.025"/>
        </geometry>
      </collision>
      <collision name="Sphere.002">
        <origin xyz="0 0.09 -0.04" rpy="1.5708 0 0"/>
        <geometry>
          <sphere radius="0.025"/>
        </geometry>
      </collision>
    </link>

    <link name="l_lower">
      <inertial>
        <origin xyz="-0.0001 0.00125 -0.14482" rpy="0 0 0"/>
        <mass value="2.0"/>
        <inertia ixx="0.04215" ixy="-0.0001" ixz="-5e-05" iyy="0.03449" iyz="-0.01473" izz="0.00811"/>
      </inertial>
      <visual name="mesh.008">
        <origin xyz="-0.0001 0.00125 -0.14482" rpy="0 0 0"/>
        <geometry>
          <mesh filename="package://ETH_biped/meshes/blackbird/Assembly_Mockup_v27_011.stl" scale="1.0 1.0 1.0"/>
        </geometry>
        <material name="Material"/>
      </visual>
      <visual name="mesh.011">
        <origin xyz="0.05162 0.03693 -0.07685" rpy="0 0 0"/>
        <geometry>
          <mesh filename="package://ETH_biped/meshes/blackbird/Assembly_Mockup_v27_014.stl" scale="1.0 1.0 1.0"/>
        </geometry>
        <material name="Material"/>
      </visual>
      <collision name="mesh.011">
        <origin xyz="0.028 0.03693 -0.07688" rpy="1.5708 0 1.5708"/>
        <geometry>
          <cylinder radius="0.055" length="0.088"/>
        </geometry>
      </collision>
    </link>

    <link name="l_upper">
      <inertial>
        <origin xyz="0.00043 0.04822 -0.10773" rpy="0 0 0"/>
        <mass value="1.0"/>
        <inertia ixx="0.04548" ixy="-0.00012" ixz="5e-05" iyy="0.0388" iyz="0.01517" izz="0.00738"/>
      </inertial>
      <visual name="mesh.010">
        <origin xyz="0.00043 0.04822 -0.10773" rpy="0 0 0"/>
        <geometry>
          <mesh filename="package://ETH_biped/meshes/blackbird/Assembly_Mockup_v27_013.stl" scale="1.0 1.0 1.0"/>
        </geometry>
        <material name="Material"/>
      </visual>
    </link>

    <link name="l_yaw">
      <inertial>
        <origin xyz="0 0 0.03518" rpy="0 0 0"/>
        <mass value="2.4"/>
        <inertia ixx="0.00566" ixy="0" ixz="4e-05" iyy="0.01138" iyz="0" izz="0.00912"/>
      </inertial>
      <visual name="mesh.004">
        <origin xyz="0 0 0.03518" rpy="0 0 0"/>
        <geometry>
          <mesh filename="package://ETH_biped/meshes/blackbird/Assembly_Mockup_v27_005.stl" scale="1.0 1.0 1.0"/>
        </geometry>
        <material name="Material"/>
      </visual>
      <collision name="mesh.004">
        <origin xyz="0 0 0.00075" rpy="1.5708 0 1.5708"/>
        <geometry>
          <cylinder radius="0.0525" length="0.209"/>
        </geometry>
      </collision>
    </link>

    <link name="r_ab_ad">
      <inertial>
        <origin xyz="-8e-05 0.02445 -0.00143" rpy="0 0 0"/>
        <mass value="1.2"/>
        <inertia ixx="0.00196" ixy="0" ixz="0" iyy="0.00133" iyz="-2e-05" izz="0.00229"/>
      </inertial>
      <visual name="mesh.003">
        <origin xyz="-8e-05 0.02445 -0.00143" rpy="0 0 0"/>
        <geometry>
          <mesh filename="package://ETH_biped/meshes/blackbird/Assembly_Mockup_v27_004.stl" scale="1.0 1.0 1.0"/>
        </geometry>
        <material name="Material"/>
      </visual>
      <collision name="mesh.003">
        <origin xyz="0 0.00015 -0.00044" rpy="0 0 0"/>
        <geometry>
          <cylinder radius="0.055" length="0.0759"/>
        </geometry>
      </collision>
    </link>

    <link name="r_foot">
      <inertial>
        <origin xyz="0 0.00325 -0.02828" rpy="0 0 0"/>
        <mass value="0.5"/>
        <inertia ixx="0.00163" ixy="0" ixz="0" iyy="0.001" iyz="-5e-05" izz="0.00151"/>
      </inertial>
      <visual name="Cylinder.002">
        <origin xyz="0 0.07 -0.05247" rpy="1.5708 0 0"/>
        <geometry>
          <cylinder radius="0.01" length="0.04"/>
        </geometry>
        <material name="ceramic"/>
      </visual>
      <visual name="Cylinder.003">
        <origin xyz="0 -0.07 -0.05247" rpy="1.5708 0 0"/>
        <geometry>
          <cylinder radius="0.01" length="0.04"/>
        </geometry>
        <material name="Material"/>
      </visual>
      <visual name="Sphere.004">
        <origin xyz="0 0.05 -0.05247" rpy="1.5708 0 0"/>
        <geometry>
          <sphere radius="0.01"/>
        </geometry>
        <material name="Material"/>
      </visual>
      <visual name="Sphere.005">
        <origin xyz="0 0.09 -0.05247" rpy="1.5708 0 0"/>
        <geometry>
          <sphere radius="0.01"/>
        </geometry>
        <material name="Material"/>
      </visual>
      <visual name="Sphere.006">
        <origin xyz="0 -0.05 -0.05247" rpy="1.5708 0 0"/>
        <geometry>
          <sphere radius="0.01"/>
        </geometry>
        <material name="Material"/>
      </visual>
      <visual name="Sphere.007">
        <origin xyz="0 -0.09 -0.05247" rpy="1.5708 0 0"/>
        <geometry>
          <sphere radius="0.01"/>
        </geometry>
        <material name="Material"/>
      </visual>
      <visual name="mesh">
        <origin xyz="0 0.00325 -0.02828" rpy="0 0 0"/>
        <geometry>
          <mesh filename="package://ETH_biped/meshes/blackbird/Assembly_Mockup_v27.stl" scale="1.0 1.0 1.0"/>
        </geometry>
        <material name="Material"/>
      </visual>
      <collision name="Sphere.005">
        <origin xyz="0 0.09 -0.04" rpy="1.5708 0 0"/>
        <geometry>
          <sphere radius="0.025"/>
        </geometry>
      </collision>
      <collision name="Sphere.007">
        <origin xyz="0 -0.09 -0.04" rpy="1.5708 0 0"/>
        <geometry>
          <sphere radius="0.025"/>
        </geometry>
      </collision>
    </link>

    <link name="r_lower">
      <inertial>
        <origin xyz="-0.00018 0.00049 -0.14674" rpy="0 0 0"/>
        <mass value="2.0"/>
        <inertia ixx="0.04173" ixy="0.00012" ixz="6e-05" iyy="0.03413" iyz="-0.01457" izz="0.00804"/>
      </inertial>
      <visual name="mesh.007">
        <origin xyz="-0.00018 0.00049 -0.14674" rpy="0 0 0"/>
        <geometry>
          <mesh filename="package://ETH_biped/meshes/blackbird/Assembly_Mockup_v27_010.stl" scale="1.0 1.0 1.0"/>
        </geometry>
        <material name="Material"/>
      </visual>
      <visual name="mesh.012">
        <origin xyz="-0.05162 0.03692 -0.07686" rpy="0 0 0"/>
        <geometry>
          <mesh filename="package://ETH_biped/meshes/blackbird/Assembly_Mockup_v27_015.stl" scale="1.0 1.0 1.0"/>
        </geometry>
        <material name="Material"/>
      </visual>
      <collision name="mesh.012">
        <origin xyz="-0.028 0.03693 -0.07688" rpy="1.5708 0 1.5708"/>
        <geometry>
          <cylinder radius="0.055" length="0.088"/>
        </geometry>
      </collision>
    </link>

    <link name="r_upper">
      <inertial>
        <origin xyz="-0.00228 0.0512 -0.11337" rpy="0 0 0"/>
        <mass value="1.0"/>
        <inertia ixx="0.04446" ixy="0.00018" ixz="-7e-05" iyy="0.03796" iyz="0.0148" izz="0.00723"/>
      </inertial>
      <visual name="mesh.006">
        <origin xyz="-0.00228 0.0512 -0.11337" rpy="0 0 0"/>
        <geometry>
          <mesh filename="package://ETH_biped/meshes/blackbird/Assembly_Mockup_v27_009.stl" scale="1.0 1.0 1.0"/>
        </geometry>
        <material name="Material"/>
      </visual>
    </link>

    <link name="r_yaw">
      <inertial>
        <origin xyz="0 0 0.03517" rpy="0 0 0"/>
        <mass value="2.4"/>
        <inertia ixx="0.00565" ixy="0" ixz="-4e-05" iyy="0.01138" iyz="0" izz="0.00912"/>
      </inertial>
      <visual name="mesh.005">
        <origin xyz="0 0 0.03517" rpy="0 0 0"/>
        <geometry>
          <mesh filename="package://ETH_biped/meshes/blackbird/Assembly_Mockup_v27_006.stl" scale="1.0 1.0 1.0"/>
        </geometry>
        <material name="Material"/>
      </visual>
      <collision name="mesh.005">
        <origin xyz="0 0 0.00075" rpy="1.5708 0 1.5708"/>
        <geometry>
          <cylinder radius="0.0525" length="0.209"/>
        </geometry>
      </collision>
    </link>

    <link name="torso">
      <inertial>
        <origin xyz="0 -0.09385 0.03683" rpy="0 0 0"/>
        <mass value="4.4"/>
        <inertia ixx="0.00838" ixy="0" ixz="0" iyy="0.00298" iyz="0" izz="0.0088"/>
      </inertial>
      <visual name="mesh.001">
        <origin xyz="0 -0.09385 0.03683" rpy="0 0 0"/>
        <geometry>
          <mesh filename="package://ETH_biped/meshes/blackbird/Assembly_Mockup_v27_001.stl" scale="1.0 1.0 1.0"/>
        </geometry>
        <material name="teal"/>
      </visual>
      <visual name="mesh.013">
        <origin xyz="-1e-05 0.10381 0.00587" rpy="0 0 0"/>
        <geometry>
          <mesh filename="package://ETH_biped/meshes/blackbird/Assembly_Mockup_v27_016.stl" scale="1.0 1.0 1.0"/>
        </geometry>
        <material name="Material"/>
      </visual>
      <visual name="mesh.014">
        <origin xyz="0 -0.071 0.005" rpy="0 0 0"/>
        <geometry>
          <mesh filename="package://ETH_biped/meshes/blackbird/Assembly_Mockup_v27_017.stl" scale="1.0 1.0 1.0"/>
        </geometry>
        <material name="Material"/>
      </visual>
      <collision name="mesh.001">
        <origin xyz="0 -0.0275 0.0175" rpy="0 0 0"/>
        <geometry>
          <box size="0.16028 0.33 0.145"/>
        </geometry>
      </collision>
      <collision name="mesh.002">
        <origin xyz="0.15 0.10367 -0.00044" rpy="1.5708 0 0"/>
        <geometry>
          <cylinder radius="0.055" length="0.0759"/>
        </geometry>
      </collision>
      <collision name="mesh.003">
        <origin xyz="-0.15 0.10367 -0.00044" rpy="1.5708 0 0"/>
        <geometry>
          <cylinder radius="0.055" length="0.0759"/>
        </geometry>
      </collision>
    </link>

    <joint name="l_hip_roll" type="revolute">
      <origin xyz="0.15 0 0" rpy="0 0 0"/>
      <parent link="torso"/>
      <child link="l_ab_ad"/>
      <axis xyz="0 -1.0 0"/>
      <limit lower="-2" upper="2" effort="50" velocity="20"/>
    </joint>

    <joint name="l_ankle" type="revolute">
      <origin xyz="0 -0.1529 -0.42302" rpy="0 0 0"/>
      <parent link="l_lower"/>
      <child link="l_foot"/>
      <axis xyz="1.0 0 0"/>
      <limit lower="-1.5708" upper="0.69813" effort="50" velocity="20"/>
    </joint>

    <joint name="l_knee" type="revolute">
      <origin xyz="0 0.1529 -0.42302" rpy="0 0 0"/>
      <parent link="l_upper"/>
      <child link="l_lower"/>
      <axis xyz="1.0 0 0"/>
      <limit lower="-2.0944" upper="0.34907" effort="50" velocity="20"/>
    </joint>

    <joint name="l_hip_pitch" type="revolute">
      <origin xyz="0 0 0" rpy="0 0 0"/>
      <parent link="l_yaw"/>
      <child link="l_upper"/>
      <axis xyz="1.0 0 0"/>
      <limit lower="-1.91986" upper="1.22173" effort="50" velocity="20"/>
    </joint>

    <joint name="l_hip_yaw" type="revolute">
      <origin xyz="0 0 -0.1295" rpy="0 0 0"/>
      <parent link="l_ab_ad"/>
      <child link="l_yaw"/>
      <axis xyz="0 0 1.0"/>
      <limit lower="-2" upper="2" effort="50" velocity="20"/>
    </joint>

    <joint name="r_hip_roll" type="revolute">
      <origin xyz="-0.15 0 0" rpy="0 0 0"/>
      <parent link="torso"/>
      <child link="r_ab_ad"/>
      <axis xyz="0 -1.0 0"/>
      <limit lower="-2" upper="2" effort="50" velocity="20"/>
    </joint>

    <joint name="r_ankle" type="revolute">
      <origin xyz="0 -0.1529 -0.42302" rpy="0 0 0"/>
      <parent link="r_lower"/>
      <child link="r_foot"/>
      <axis xyz="1.0 0 0"/>
      <limit lower="-1.5708" upper="0.69813" effort="50" velocity="20"/>
    </joint>

    <joint name="r_knee" type="revolute">
      <origin xyz="0 0.1529 -0.42302" rpy="0 0 0"/>
      <parent link="r_upper"/>
      <child link="r_lower"/>
      <axis xyz="1.0 0 0"/>
      <limit lower="-2.0944" upper="0.34907" effort="50" velocity="20"/>
    </joint>

    <joint name="r_hip_pitch" type="revolute">
      <origin xyz="0 0 0" rpy="0 0 0"/>
      <parent link="r_yaw"/>
      <child link="r_upper"/>
      <axis xyz="1.0 0 0"/>
      <limit lower="-1.91986" upper="1.22173" effort="50" velocity="20"/>
    </joint>

    <joint name="r_hip_yaw" type="revolute">
      <origin xyz="0 0 -0.1295" rpy="0 0 0"/>
      <parent link="r_ab_ad"/>
      <child link="r_yaw"/>
      <axis xyz="0 0 1.0"/>
      <limit lower="-2" upper="2" effort="50" velocity="20"/>
    </joint>

    <joint name="world_to_torso" type="fixed">
        <origin rpy="0 0 0" xyz="0 0 1"/>
        <parent link="world"/>
        <child link="torso"/>
    </joint>

    <material name="Material">
      <color rgba="0.25 0.25 0.25 1.0"/>
    </material>


  </robot>
